Traceback (most recent call last):
  File "/home/runner/work/qmlcourse/qmlcourse/.venv/lib/python3.8/site-packages/jupyter_cache/executors/utils.py", line 51, in single_nb_execution
    executenb(
  File "/home/runner/work/qmlcourse/qmlcourse/.venv/lib/python3.8/site-packages/nbclient/client.py", line 1112, in execute
    return NotebookClient(nb=nb, resources=resources, km=km, **kwargs).execute()
  File "/home/runner/work/qmlcourse/qmlcourse/.venv/lib/python3.8/site-packages/nbclient/util.py", line 74, in wrapped
    return just_run(coro(*args, **kwargs))
  File "/home/runner/work/qmlcourse/qmlcourse/.venv/lib/python3.8/site-packages/nbclient/util.py", line 53, in just_run
    return loop.run_until_complete(coro)
  File "/opt/hostedtoolcache/Python/3.8.11/x64/lib/python3.8/asyncio/base_events.py", line 616, in run_until_complete
    return future.result()
  File "/home/runner/work/qmlcourse/qmlcourse/.venv/lib/python3.8/site-packages/nbclient/client.py", line 553, in async_execute
    await self.async_execute_cell(
  File "/home/runner/work/qmlcourse/qmlcourse/.venv/lib/python3.8/site-packages/nbclient/client.py", line 857, in async_execute_cell
    self._check_raise_for_error(cell, exec_reply)
  File "/home/runner/work/qmlcourse/qmlcourse/.venv/lib/python3.8/site-packages/nbclient/client.py", line 760, in _check_raise_for_error
    raise CellExecutionError.from_cell_and_msg(cell, exec_reply_content)
nbclient.exceptions.CellExecutionError: An error occurred while executing the following cell:
------------------
example_list = list(["—á—Ç–æ-—Ç–æ", "—Å"])
print(f"–ú–µ—Ç–æ–¥ append –∏–º–µ–µ—Ç —Ç–∏–ø {example_list.append}")

# –≤–æ—Ç —Ç–∞–∫ –º–æ–∂–Ω–æ –≤—ã–∑–≤–∞—Ç—å –º–µ—Ç–æ–¥, –∏–∑–º–µ–Ω—è—è —Å–∞–º —ç–∫–∑–µ–º–ø–ª—è—Ä –∫–ª–∞—Å—Å–∞
example_list.append("—á–µ–º-—Ç–æ")

# –∞ –≤–æ—Ç —Ç–∞–∫ –º–æ–∂–Ω–æ –æ–±—Ä–∞—Ç–∏—Ç—å—Å—è –∫ –∞—Ç—Ä–∏–±—É—Ç—É –∫–æ–Ω–∫—Ä–µ—Ç–Ω–æ–≥–æ –æ–±—ä–µ–∫—Ç–∞
attr_value = x.__doc__
print(f"–ó–Ω–∞—á–µ–Ω–∏–µ –∞—Ç—Ä–∏–±—É—Ç–∞: {attr_value}")
------------------

[0;31m---------------------------------------------------------------------------[0m
[0;31mNameError[0m                                 Traceback (most recent call last)
[0;32m/tmp/ipykernel_2045/1658473650.py[0m in [0;36m<module>[0;34m[0m
[1;32m      6[0m [0;34m[0m[0m
[1;32m      7[0m [0;31m# –∞ –≤–æ—Ç —Ç–∞–∫ –º–æ–∂–Ω–æ –æ–±—Ä–∞—Ç–∏—Ç—å—Å—è –∫ –∞—Ç—Ä–∏–±—É—Ç—É –∫–æ–Ω–∫—Ä–µ—Ç–Ω–æ–≥–æ –æ–±—ä–µ–∫—Ç–∞[0m[0;34m[0m[0;34m[0m[0;34m[0m[0m
[0;32m----> 8[0;31m [0mattr_value[0m [0;34m=[0m [0mx[0m[0;34m.[0m[0m__doc__[0m[0;34m[0m[0;34m[0m[0m
[0m[1;32m      9[0m [0mprint[0m[0;34m([0m[0;34mf"–ó–Ω–∞—á–µ–Ω–∏–µ –∞—Ç—Ä–∏–±—É—Ç–∞: {attr_value}"[0m[0;34m)[0m[0;34m[0m[0;34m[0m[0m

[0;31mNameError[0m: name 'x' is not defined
NameError: name 'x' is not defined

